<?xml version="1.0" ?>
<robot xmlns:xacro="http://ros.org/wiki/xacro">
 	<!--Joints-->
	<!-- Fixed Joint between Base_footprint and Robot Base-->
  <joint name="base_fixed_joint" type="fixed">
    <parent link="base_footprint"/>
    <child link="base_link"/>
    <origin xyz="0.0 0.0 0.05"/>
  </joint>

	<joint name="wheel_left_joint" type="continuous">
		<parent link="base_footprint"/>
		<child link="wheel_left"/>
		<axis xyz="0 0 1" rpy="0 0 0" />
		<origin xyz="0.0 0.12 0.0" rpy="$(eval pi/2) 0 $(eval pi)"/>
	</joint>

	<joint name="wheel_rigth_joint" type="continuous">
		<parent link="base_footprint"/>
		<child link="wheel_rigth"/>
		<axis xyz="0 0 1" rpy="0 0 0" />
		<origin xyz="0.0 -0.12 0.0" rpy="$(eval pi/2) 0 $(eval pi)"/>
	</joint>

	<joint name="pivot_back_joint" type="continuous">
		<parent link="base_footprint"/>
		<child link="pivot_back"/>
		<axis xyz="0 0 1" rpy="0 0 0" />
		<origin xyz="-0.12 0.0 0.0" rpy="$(eval pi/2) 0 0"/>
	</joint>

	<joint name="pivot_front_joint" type="continuous">
		<parent link="base_footprint"/>
		<child link="pivot_front"/>
		<axis xyz="0 0 1" rpy="0 0 0" />
		<origin xyz="0.12 0.0 0.0" rpy="$(eval pi/2) 0 0"/>
	</joint>


</robot>
