<?xml version="1.0" ?>
<robot xmlns:xacro="http://ros.org/wiki/xacro">
 	<!--Joints-->
	<!--joint1-->
	<joint name="joint_1" type="revolute">
    <origin rpy="0 0 0" xyz="0 0 0.3"/>
    <parent link="base_arm"/>
    <child link="link1"/>
    <axis xyz="0 0 1"/>
    <limit effort="1000" lower="-3.1416" upper="3.1416" velocity="2.618"/>
  </joint>
  <transmission name="trans_joint_1">
		<type>transmission_interface/SimpleTransmission</type>
		<joint name="joint_1">
			<hardwareInterface>hardware_interface/PositionJointInterface</hardwareInterface>
		</joint>
		<actuator name="motor_joint_1">
			<hardwareInterface>hardware_interface/PositionJointInterface</hardwareInterface>
			<mechanicalReduction>1</mechanicalReduction>
		</actuator>
  </transmission>
	<!--joint2-->
	<joint name="joint_2" type="revolute">
    <origin rpy="0 0 0" xyz="0 0.11 0"/>
    <parent link="link1"/>
    <child link="link2"/>
    <axis xyz="0 1 0"/>
    <limit effort="1000" lower="-3.1416" upper="3.1416" velocity="2.618"/>
  </joint>
	<transmission name="trans_joint_2">
		<type>transmission_interface/SimpleTransmission</type>
		<joint name="joint_2">
			<hardwareInterface>hardware_interface/PositionJointInterface</hardwareInterface>
		</joint>
		<actuator name="motor_joint_2">
			<hardwareInterface>hardware_interface/PositionJointInterface</hardwareInterface>
			<mechanicalReduction>1</mechanicalReduction>
		</actuator>
  </transmission>
	<!--joint3-->
	<joint name="joint_3" type="revolute">
    <origin rpy="0 0 0" xyz="0.25 -0.05 0"/>
    <parent link="link2"/>
    <child link="link3"/>
    <axis xyz="0 1 0"/>
    <limit effort="1000" lower="-3.1416" upper="3.1416" velocity="2.618"/>
  </joint>
	<transmission name="trans_joint_3">
		<type>transmission_interface/SimpleTransmission</type>
		<joint name="joint_3">
			<hardwareInterface>hardware_interface/PositionJointInterface</hardwareInterface>
		</joint>
		<actuator name="motor_joint_3">
			<hardwareInterface>hardware_interface/PositionJointInterface</hardwareInterface>
			<mechanicalReduction>1</mechanicalReduction>
		</actuator>
  </transmission>
	<!--joint4-->
	<joint name="joint_4" type="revolute">
    <origin rpy="0 0 0" xyz="0.2 0.025 0"/>
    <parent link="link3"/>
    <child link="link4"/>
    <axis xyz="1 0 0"/>
    <limit effort="1000" lower="-3.1416" upper="3.1416" velocity="2.618"/>
  </joint>
	<transmission name="trans_joint_4">
		<type>transmission_interface/SimpleTransmission</type>
		<joint name="joint_4">
			<hardwareInterface>hardware_interface/PositionJointInterface</hardwareInterface>
		</joint>
		<actuator name="motor_joint_4">
			<hardwareInterface>hardware_interface/PositionJointInterface</hardwareInterface>
			<mechanicalReduction>1</mechanicalReduction>
		</actuator>
  </transmission>
	<!--joint5-->
	<joint name="joint_5" type="revolute">
    <origin rpy="0 0 0" xyz="0.03 0 0"/>
    <parent link="link4"/>
    <child link="link5"/>
    <axis xyz="0 1 0"/>
    <limit effort="1000" lower="-3.1416" upper="3.1416" velocity="2.618"/>
  </joint>
	<transmission name="trans_joint_5">
		<type>transmission_interface/SimpleTransmission</type>
		<joint name="joint_5">
			<hardwareInterface>hardware_interface/PositionJointInterface</hardwareInterface>
		</joint>
		<actuator name="motor_joint_5">
			<hardwareInterface>hardware_interface/PositionJointInterface</hardwareInterface>
			<mechanicalReduction>1</mechanicalReduction>
		</actuator>
  </transmission>
	<!--joint6-->
	<joint name="joint_6" type="revolute">
    <origin rpy="0 0 0" xyz="0.01 0 0"/>
    <parent link="link5"/>
    <child link="link6"/>
    <axis xyz="1 0 0"/>
    <limit effort="1000" lower="-3.1416" upper="3.1416" velocity="2.618"/>
  </joint>
	<transmission name="trans_joint_6">
		<type>transmission_interface/SimpleTransmission</type>
		<joint name="joint_6">
			<hardwareInterface>hardware_interface/PositionJointInterface</hardwareInterface>
		</joint>
		<actuator name="motor_joint_6">
			<hardwareInterface>hardware_interface/PositionJointInterface</hardwareInterface>
			<mechanicalReduction>1</mechanicalReduction>
		</actuator>
  </transmission>
</robot>
